<?xml version="1.0"?>
<sdf version='1.6'>
  <model name='cartpole'>

    <link name="rail">
      <pose frame=''>0 0 0.05 0 0 0</pose>
      <inertial>
        <pose frame=''>0 0 0 0 0 0</pose>
        <mass>100</mass>
        <inertia>
          <ixx>10</ixx>
          <iyy>10</iyy>
          <izz>10</izz>
          <ixy>0</ixy>
          <iyz>0</iyz>
          <ixz>0</ixz>
        </inertia>
      </inertial>
      <collision name="rail_collision">
        <geometry>
          <box>
            <size>10 0.1 0.1</size>
          </box>
        </geometry>
      </collision>
      <visual name="rail_visual">
        <cast_shadows>false</cast_shadows>
        <transparency>0.2</transparency>
        <geometry>
          <box>
            <size>10 0.1 0.1</size>
          </box>
        </geometry>
        <material>
          <ambient>0.2 0.2 0.2 1</ambient>
          <diffuse>0.2 0.2 0.2 1</diffuse>
          <specular>0.2 0.2 0.2 1</specular>
        </material>
      </visual>
      <self_collide>0</self_collide>
      <enable_wind>0</enable_wind>
      <kinematic>0</kinematic>
    </link>
    <joint name='rail_joint' type='fixed'>
      <pose frame=''>0 0 0.05 0 0 0</pose>
      <parent>world</parent>
      <child>rail</child>
    </joint>

    <link name='cart'>
      <pose frame=''>0 0 0.15 0 0 0</pose>
      <inertial>
        <pose frame=''>0 0 0 0 0 0</pose>
        <mass>1</mass>
        <inertia>
          <ixx>4.2e-03</ixx>
          <ixy>0</ixy>
          <ixz>0</ixz>
          <iyy>4.2e-03</iyy>
          <iyz>0</iyz>
          <izz>7.5e-03</izz>
        </inertia>
      </inertial>
      <collision name='cart_collision'>
        <pose frame=''>0 0 0 0 0 0</pose>
        <geometry>
          <box>
            <size>0.3 0.3 0.1</size>
          </box>
        </geometry>
      </collision>
      <visual name='cart_visual'>
        <cast_shadows>false</cast_shadows>
        <transparency>0</transparency>
        <pose frame=''>0 0 0 0 -0 0</pose>
        <geometry>
          <box>
            <size>0.3 0.3 0.1</size>
          </box>
        </geometry>
        <material>
          <ambient>1 0 0 1</ambient>
          <diffuse>1 0 0 1</diffuse>
          <specular>1 0 0 1</specular>
        </material>
      </visual>
    </link>
    <joint name='cart_joint' type='prismatic'>
      <pose frame=''>0 0 0.1 0 0 0</pose>
      <parent>rail</parent>
      <child>cart</child>
      <axis>
        <xyz>1 0 0</xyz>
        <limit>
          <lower>-4</lower>
          <upper>4</upper>
        </limit>
      </axis>
      <use_parent_model_frame>1</use_parent_model_frame>
    </joint>

    <link name='pole'>
      <pose frame=''>0 0 0.7 0 0 0</pose>
      <inertial>
        <pose frame=''>0 0 0 0 0 0</pose>
        <mass>0.5</mass>
        <inertia>
          <ixx>4.2e-02</ixx>
          <ixy>0</ixy>
          <ixz>0</ixz>
          <iyy>4.2e-02</iyy>
          <iyz>0</iyz>
          <izz>8.3e-05</izz>
        </inertia>
      </inertial>
      <collision name='pole_collision'>
        <pose frame=''>0 0 0 0 0 0</pose>
        <geometry>
          <box>
            <size>0.04 0.04 1</size>
          </box>
        </geometry>
      </collision>
      <visual name='pole_visual'>
        <cast_shadows>false</cast_shadows>
        <transparency>0</transparency>
        <pose frame=''>0 0 0 0 0 0</pose>
        <geometry>
          <box>
            <size>0.04 0.04 1</size>
          </box>
        </geometry>
        <material>
          <ambient>0.5 0.5 0.5 1</ambient>
          <diffuse>0.5 0.5 0.5 1</diffuse>
          <specular>0.5 0.5 0.5 1</specular>
        </material>
      </visual>
    </link>
    <joint name='pole_joint' type='revolute'>
      <pose frame=''>0 0 -0.5 0 0 0</pose>
      <parent>cart</parent>
      <child>pole</child>
      <axis>
        <xyz>0 1 0</xyz>
        <limit>
          <lower>-1e+16</lower>
          <upper>1e+16</upper>
        </limit>
        <dynamics>
          <spring_reference>0</spring_reference>
          <spring_stiffness>0</spring_stiffness>
        </dynamics>
        <use_parent_model_frame>1</use_parent_model_frame>
      </axis>
    </joint>
  
  </model>
</sdf>